Workbook

Sheet Daily Summary
A1: Date | B1: Period | C1: Week Start (Mon) | D1: Steps | E1: Distance (km) | F1: Run Distance (km) | G1: Activity Calories (kcal) | H1: Active Minutes | I1: Resting HR (bpm) | J1: Avg HR (bpm) | K1: Max HR (bpm) | L1: Sleeping HR (bpm) | M1: Vigorous Minutes (HR ≥ 140) | N1: HRV Baseline (monthly, ms) | O1: Workout(s) | P1: Workout Count | Q1: Workout Minutes | R1: Workout Calories (kcal) | S1: Total Sleep (min) | T1: Deep Sleep (min) | U1: Light Sleep (min) | V1: REM Sleep (min) | W1: Time Awake (min) | X1: Fell Asleep (IST) | Y1: Woke Up (IST) | Z1: Naps (count) | AA1: Est. Energy Burned (kcal)
A2: 46154 | B2: P1 | C2: =A2-WEEKDAY(A2,3) -> 46153 | D2: 2567 | E2: 1.669 | F2: 1.437 | G2: 10 | H2: 61 | I2: 43 | J2: 60.357639 | K2: 115 | M2: 0 | N2: 91 | P2: 0 | Q2: 0 | R2: 0 | S2: =IF(COUNT(T2:V2)=3,T2+U2+V2,"") -> 543 | T2: 99 | U2: 314 | V2: 130 | W2: 3 | X2: 46154.103 | Y2: 46154.483 | Z2: 1 | AA2: 1699.6196
A3: 46155 | B3: P1 | C3: =A3-WEEKDAY(A3,3) -> 46153 | D3: 10821 | E3: 7.631 | F3: 5.734 | G3: 1448 | H3: 204 | I3: 40 | J3: 71.352941 | K3: 178 | L3: 44.31713 | M3: 102 | N3: 91 | O3: Strength/Gym (28 min); Indoor cardio/HIIT (94 min) | P3: 2 | Q3: 121.35 | R3: 1261 | S3: =IF(COUNT(T3:V3)=3,T3+U3+V3,"") -> 427 | T3: 65 | U3: 285 | V3: 77 | W3: 4 | X3: 46155.142 | Y3: 46155.442 | Z3: 1 | AA3: 3348.3664
A4: 46156 | B4: P1 | C4: =A4-WEEKDAY(A4,3) -> 46153 | D4: 2862 | E4: 1.864 | F4: 1.639 | G4: 369 | H4: 86 | I4: 40 | J4: 61.484891 | K4: 126 | L4: 45.670534 | M4: 0 | N4: 91 | O4: Strength/Gym (55 min) | P4: 1 | Q4: 55.366667 | R4: 257 | S4: =IF(COUNT(T4:V4)=3,T4+U4+V4,"") -> 514 | T4: 95 | U4: 289 | V4: 130 | W4: 8 | X4: 46156.128 | Y4: 46156.49 | Z4: 0 | AA4: 1977.2058
A5: 46157 | B5: P1 | C5: =A5-WEEKDAY(A5,3) -> 46153 | D5: 3634 | E5: 2.362 | F5: 2.087 | G5: 275 | H5: 153 | I5: 40 | J5: 57.24911 | K5: 109 | L5: 42.983491 | M5: 0 | N5: 91 | O5: Strength/Gym (52 min) | P5: 1 | Q5: 51.616667 | R5: 114 | S5: =IF(COUNT(T5:V5)=3,T5+U5+V5,"") -> 489 | T5: 60 | U5: 291 | V5: 138 | W5: 5 | X5: 46157.178 | Y5: 46157.521 | Z5: 3 | AA5: 1862.188
A6: 46158 | B6: P1 | C6: =A6-WEEKDAY(A6,3) -> 46153 | D6: 4525 | E6: 3.078 | F6: 2.449 | G6: 180 | H6: 46 | I6: 40 | J6: 58.061649 | K6: 116 | L6: 44.812217 | M6: 0 | N6: 91 | P6: 0 | Q6: 0 | R6: 0 | S6: =IF(COUNT(T6:V6)=3,T6+U6+V6,"") -> 442 | T6: 60 | U6: 287 | V6: 95 | W6: 13 | X6: 46158.168 | Y6: 46158.484 | Z6: 0 | AA6: 1782.104
A7: 46159 | B7: P1 | C7: =A7-WEEKDAY(A7,3) -> 46153 | D7: 12514 | E7: 8.995 | F7: 6.896 | G7: 398 | H7: 254 | I7: 45 | J7: 71.195652 | K7: 160 | L7: 59.968379 | M7: 22 | N7: 91 | P7: 0 | Q7: 0 | R7: 0 | S7: =IF(COUNT(T7:V7)=3,T7+U7+V7,"") -> 418 | T7: 86 | U7: 196 | V7: 136 | W7: 2 | X7: 46159.308 | Y7: 46159.6 | Z7: 0 | AA7: 2118.6555
A8: 46160 | B8: P1 | C8: =A8-WEEKDAY(A8,3) -> 46160 | D8: 11694 | E8: 9.131 | F8: 7.007 | G8: 859 | H8: 163 | I8: 44 | J8: 68.093114 | K8: 189 | L8: 50.452756 | M8: 33 | N8: 91 | O8: Strength/Gym (45 min); Running (31 min) | P8: 2 | Q8: 76.066667 | R8: 633.26315 | S8: =IF(COUNT(T8:V8)=3,T8+U8+V8,"") -> 493 | T8: 81 | U8: 299 | V8: 113 | W8: 13 | X8: 46160.133 | Y8: 46160.484 | Z8: 0 | AA8: 2523.9953
A9: 46161 | B9: P1 | C9: =A9-WEEKDAY(A9,3) -> 46160 | D9: 6979 | E9: 5.01 | F9: 3.911 | G9: 472 | H9: 107 | I9: 40 | J9: 59.022917 | K9: 109 | L9: 45.879699 | M9: 0 | N9: 91 | O9: Walk/Jog (44 min); Strength/Gym (60 min) | P9: 2 | Q9: 103.5 | R9: 353.92671 | S9: =IF(COUNT(T9:V9)=3,T9+U9+V9,"") -> 520 | T9: 63 | U9: 336 | V9: 121 | W9: 8 | X9: 46161.207 | Y9: 46161.574 | Z9: 0 | AA9: 2077.8695
A10: 46162 | B10: P1 | C10: =A10-WEEKDAY(A10,3) -> 46160 | D10: 1948 | E10: 1.268 | F10: 1.067 | G10: 537 | H10: 43 | I10: 40 | J10: 61.653738 | K10: 133 | L10: 44.02439 | M10: 0 | N10: 91 | O10: Indoor workout (51 min) | P10: 1 | Q10: 50.883333 | R10: 348 | S10: =IF(COUNT(T10:V10)=3,T10+U10+V10,"") -> 495 | T10: 51 | U10: 294 | V10: 150 | W10: 11 | X10: 46162.168 | Y10: 46162.519 | Z10: 0 | AA10: 2032.5907
A11: 46163 | B11: P1 | C11: =A11-WEEKDAY(A11,3) -> 46160 | D11: 12019 | E11: 9.247 | F11: 7.179 | G11: 892 | H11: 158 | I11: 42 | J11: 72.71595 | K11: 187 | L11: 49.413978 | M11: 27 | N11: 91 | O11: Strength/Gym (51 min); Running (28 min) | P11: 2 | Q11: 79.133333 | R11: 641.56531 | S11: =IF(COUNT(T11:V11)=3,T11+U11+V11,"") -> 370 | T11: 95 | U11: 209 | V11: 66 | W11: 4 | X11: 46163.166 | Y11: 46163.426 | Z11: 5 | AA11: 2555.9615
A12: 46164 | B12: P1 | C12: =A12-WEEKDAY(A12,3) -> 46160 | D12: 2337 | E12: 1.527 | F12: 1.313 | G12: 263 | H12: 44 | I12: 44 | J12: 60.005076 | K12: 122 | L12: 50.598174 | M12: 0 | N12: 91 | O12: Strength/Gym (44 min) | P12: 1 | Q12: 44.266667 | R12: 174 | S12: =IF(COUNT(T12:V12)=3,T12+U12+V12,"") -> 471 | T12: 70 | U12: 299 | V12: 102 | W12: 5 | X12: 46164.274 | Y12: 46164.604 | Z12: 9 | AA12: 1869.4543
A13: 46165 | B13: P1 | C13: =A13-WEEKDAY(A13,3) -> 46160 | D13: 7524 | E13: 5.164 | F13: 3.996 | G13: 1024 | H13: 162 | I13: 40 | J13: 69.906926 | K13: 179 | L13: 45.424242 | M13: 68 | N13: 91 | O13: High-intensity indoor (85) (71 min) | P13: 1 | Q13: 71.45 | R13: 850 | S13: =IF(COUNT(T13:V13)=3,T13+U13+V13,"") -> 524 | T13: 89 | U13: 305 | V13: 130 | W13: 4 | X13: 46165.181 | Y13: 46165.548 | Z13: 0 | AA13: 2785.4266
A14: 46166 | B14: P1 | C14: =A14-WEEKDAY(A14,3) -> 46160 | D14: 19723 | E14: 15.528 | F14: 11.546 | G14: 1692 | H14: 187 | I14: 53 | J14: 84.096705 | K14: 180 | L14: 57.64 | M14: 101 | N14: 91 | O14: Running (40 min); Running (19 min); Indoor cardio/HIIT (66 min) | P14: 3 | Q14: 124.51667 | R14: 1421.5362 | S14: =IF(COUNT(T14:V14)=3,T14+U14+V14,"") -> 192 | T14: 43 | U14: 117 | V14: 32 | W14: 3 | X14: 46166.115 | Y14: 46166.25 | Z14: 7 | AA14: 3517.654
A15: 46167 | B15: P1 | C15: =A15-WEEKDAY(A15,3) -> 46167 | D15: 1983 | E15: 1.289 | F15: 1.103 | G15: 235 | H15: 87 | I15: 45 | J15: 60.953081 | K15: 117 | L15: 53.39645 | M15: 0 | N15: 91 | O15: Strength/Gym (37 min) | P15: 1 | Q15: 36.683333 | R15: 153 | S15: =IF(COUNT(T15:V15)=3,T15+U15+V15,"") -> 654 | T15: 64 | U15: 416 | V15: 174 | W15: 18 | X15: 46167.133 | Y15: 46167.599 | Z15: 0 | AA15: 1832.8747
A16: 46168 | B16: P1 | C16: =A16-WEEKDAY(A16,3) -> 46167 | D16: 9070 | E16: 6.29 | F16: 4.905 | G16: 635 | H16: 177 | I16: 45 | J16: 66.165376 | K16: 166 | L16: 49.285714 | M16: 15 | N16: 91 | O16: High-intensity indoor (85) (65 min) | P16: 1 | Q16: 64.833333 | R16: 381 | S16: =IF(COUNT(T16:V16)=3,T16+U16+V16,"") -> 144 | T16: 47 | U16: 80 | V16: 17 | W16: 2 | X16: 46168.191 | Y16: 46168.292 | Z16: 0 | AA16: 2366.6658
A17: 46169 | B17: P1 | C17: =A17-WEEKDAY(A17,3) -> 46167 | D17: 4542 | E17: 3.088 | F17: 2.483 | G17: 719 | H17: 68 | I17: 40 | J17: 60.279911 | K17: 138 | L17: 46.924658 | M17: 0 | N17: 91 | O17: Indoor workout (52 min); Strength/Gym (42 min) | P17: 2 | Q17: 93.45 | R17: 557 | S17: =IF(COUNT(T17:V17)=3,T17+U17+V17,"") -> 499 | T17: 84 | U17: 317 | V17: 98 | W17: 12 | X17: 46169.122 | Y17: 46169.476 | Z17: 9 | AA17: 2357.5027
A18: 46170 | B18: P1 | C18: =A18-WEEKDAY(A18,3) -> 46167 | D18: 2316 | E18: 1.592 | F18: 1.311 | G18: 102 | H18: 27 | I18: 43 | J18: 64.305478 | K18: 102 | L18: 52.833333 | M18: 0 | N18: 91 | P18: 0 | Q18: 0 | R18: 0 | S18: =IF(COUNT(T18:V18)=3,T18+U18+V18,"") -> 195 | T18: 35 | U18: 115 | V18: 45 | W18: 1 | X18: 46170.412 | Y18: 46170.548 | Z18: 5 | AA18: 1689.0458
A19: 46171 | B19: P1 | C19: =A19-WEEKDAY(A19,3) -> 46167 | D19: 24675 | E19: 19.511 | F19: 14.861 | G19: 1685 | H19: 235 | I19: 40 | J19: 69.67339 | K19: 179 | M19: 66 | N19: 91 | O19: Running (66 min); Walk/Jog (28 min); Indoor workout (46 min) | P19: 3 | Q19: 140.9 | R19: 1212.4852 | S19: =IF(COUNT(T19:V19)=3,T19+U19+V19,"") -> 343 | T19: 43 | U19: 211 | V19: 89 | W19: 8 | X19: 46170.949 | Y19: 46171.193 | Z19: 0 | AA19: 3369.8269
A20: 46172 | B20: P1 | C20: =A20-WEEKDAY(A20,3) -> 46167 | D20: 9755 | E20: 6.777 | F20: 5.412 | G20: 1220 | H20: 388 | I20: 43 | J20: 73.284003 | K20: 177 | M20: 55 | N20: 91 | O20: Indoor cardio/HIIT (90 min) | P20: 1 | Q20: 89.6 | R20: 878 | S20: =IF(COUNT(T20:V20)=3,T20+U20+V20,"") -> 191 | T20: 33 | U20: 128 | V20: 30 | W20: 6 | X20: 46172.439 | Y20: 46172.576 | Z20: 12 | AA20: 2908.3005
A21: 46173 | B21: P1 | C21: =A21-WEEKDAY(A21,3) -> 46167 | D21: 17695 | E21: 13.017 | F21: 9.951 | G21: 1903 | H21: 219 | I21: 40 | J21: 73.218457 | K21: 180 | L21: 43.37234 | M21: 92 | N21: 91 | O21: Running (21 min); Strength/Gym (31 min); Indoor cardio/HIIT (108 min) | P21: 3 | Q21: 159.11667 | R21: 1676.0763 | S21: =IF(COUNT(T21:V21)=3,T21+U21+V21,"") -> 353 | T21: 65 | U21: 193 | V21: 95 | W21: 4 | X21: 46173.044 | Y21: 46173.292 | Z21: 1 | AA21: 3940.9426
A22: 46174 | B22: P1 | C22: =A22-WEEKDAY(A22,3) -> 46174 | D22: 3570 | E22: 2.427 | F22: 2.021 | G22: 146 | H22: 100 | I22: 40 | J22: 56.786806 | K22: 102 | L22: 46.872727 | M22: 0 | N22: 83 | P22: 0 | Q22: 0 | R22: 0 | S22: =IF(COUNT(T22:V22)=3,T22+U22+V22,"") -> 598 | T22: 91 | U22: 339 | V22: 168 | W22: 12 | X22: 46174.153 | Y22: 46174.576 | Z22: 0 | AA22: 1741.8729
A23: 46175 | B23: P1 | C23: =A23-WEEKDAY(A23,3) -> 46174 | D23: 5128 | E23: 3.345 | F23: 2.949 | G23: 281 | H23: 243 | I23: 40 | J23: 59.336201 | K23: 94 | L23: 43.021739 | M23: 0 | N23: 83 | P23: 0 | Q23: 0 | R23: 0 | S23: =IF(COUNT(T23:V23)=3,T23+U23+V23,"") -> 209 | T23: 66 | U23: 99 | V23: 44 | W23: 4 | X23: 46175.072 | Y23: 46175.219 | Z23: 0 | AA23: 1807.5065
A24: 46176 | B24: P1 | C24: =A24-WEEKDAY(A24,3) -> 46174 | D24: 3426 | E24: 2.284 | F24: 1.954 | G24: 154 | H24: 102 | I24: 40 | J24: 55.980043 | K24: 102 | L24: 47.723005 | M24: 0 | N24: 83 | P24: 0 | Q24: 0 | R24: 0 | S24: =IF(COUNT(T24:V24)=3,T24+U24+V24,"") -> 447 | T24: 81 | U24: 279 | V24: 87 | W24: 2 | X24: 46176.031 | Y24: 46176.343 | Z24: 5 | AA24: 1735.8066
A25: 46177 | B25: P1 | C25: =A25-WEEKDAY(A25,3) -> 46174 | D25: 12506 | E25: 9.141 | F25: 7.263 | G25: 925 | H25: 278 | I25: 40 | J25: 65.658606 | K25: 184 | L25: 42.475949 | M25: 15 | N25: 83 | O25: Walk/Jog (15 min); Indoor workout (71 min) | P25: 2 | Q25: 85.933333 | R25: 498.8929 | S25: =IF(COUNT(T25:V25)=3,T25+U25+V25,"") -> 399 | T25: 68 | U25: 234 | V25: 97 | W25: 8 | X25: 46177.062 | Y25: 46177.345 | Z25: 0 | AA25: 2539.8084
A26: 46178 | B26: P1 | C26: =A26-WEEKDAY(A26,3) -> 46174 | D26: 9240 | E26: 6.724 | F26: 5.196 | G26: 308 | H26: 117 | I26: 42 | J26: 64.96544 | K26: 116 | L26: 51.567568 | M26: 0 | N26: 83 | P26: 0 | Q26: 0 | R26: 0 | S26: =IF(COUNT(T26:V26)=3,T26+U26+V26,"") -> 481 | T26: 71 | U26: 305 | V26: 105 | W26: 8 | X26: 46178.049 | Y26: 46178.389 | Z26: 0 | AA26: 1980.7321
A27: 46179 | B27: P1 | C27: =A27-WEEKDAY(A27,3) -> 46174 | D27: 8915 | E27: 6.157 | F27: 4.82 | G27: 289 | H27: 253 | I27: 43 | J27: 70.363057 | K27: 157 | L27: 50.480186 | M27: 5 | N27: 83 | P27: 0 | Q27: 0 | R27: 0 | S27: =IF(COUNT(T27:V27)=3,T27+U27+V27,"") -> 422 | T27: 94 | U27: 217 | V27: 111 | W27: 6 | X27: 46179.08 | Y27: 46179.377 | Z27: 7 | AA27: 1967.0409
A28: 46180 | B28: P1 | C28: =A28-WEEKDAY(A28,3) -> 46174 | D28: 7774 | E28: 5.14 | F28: 4.351 | G28: 374 | H28: 240 | I28: 44 | J28: 63.476923 | K28: 122 | L28: 52.671196 | M28: 0 | N28: 83 | P28: 0 | Q28: 0 | R28: 0 | S28: =IF(COUNT(T28:V28)=3,T28+U28+V28,"") -> 369 | T28: 61 | U28: 203 | V28: 105 | W28: 3 | X28: 46180.076 | Y28: 46180.335 | Z28: 0 | AA28: 1918.9742
A29: 46181 | B29: P1 | C29: =A29-WEEKDAY(A29,3) -> 46181 | D29: 5739 | E29: 3.911 | F29: 3.05 | G29: 610 | H29: 118 | I29: 40 | J29: 60.59049 | K29: 128 | L29: 48.056856 | M29: 0 | N29: 83 | O29: Strength/Gym (113 min) | P29: 1 | Q29: 113.36667 | R29: 449 | S29: =IF(COUNT(T29:V29)=3,T29+U29+V29,"") -> 294 | T29: 56 | U29: 188 | V29: 50 | W29: 4 | X29: 46181.118 | Y29: 46181.325 | Z29: 0 | AA29: 2296.5
A30: 46182 | B30: P1 | C30: =A30-WEEKDAY(A30,3) -> 46181 | D30: 9947 | E30: 6.969 | F30: 5.4 | G30: 633 | H30: 193 | I30: 40 | J30: 62.403472 | K30: 131 | L30: 46.16443 | M30: 0 | N30: 83 | O30: Strength/Gym (73 min) | P30: 1 | Q30: 72.8 | R30: 359 | S30: =IF(COUNT(T30:V30)=3,T30+U30+V30,"") -> 400 | T30: 79 | U30: 220 | V30: 101 | W30: 8 | X30: 46182.098 | Y30: 46182.381 | Z30: 0 | AA30: 2380.9126
A31: 46183 | B31: P1 | C31: =A31-WEEKDAY(A31,3) -> 46181 | D31: 6419 | E31: 4.383 | F31: 3.474 | G31: 800 | H31: 124 | I31: 44 | J31: 68.387888 | K31: 176 | L31: 48.718391 | M31: 45 | N31: 83 | O31: High-intensity indoor (85) (54 min) | P31: 1 | Q31: 54.483333 | R31: 602 | S31: =IF(COUNT(T31:V31)=3,T31+U31+V31,"") -> 345 | T31: 75 | U31: 199 | V31: 71 | W31: 2 | X31: 46183.11 | Y31: 46183.351 | Z31: 0 | AA31: 2483.0034
A32: 46184 | B32: P1 | C32: =A32-WEEKDAY(A32,3) -> 46181 | D32: 5834 | E32: 3.961 | F32: 3.255 | G32: 700 | H32: 149 | I32: 42 | J32: 63.82028 | K32: 130 | L32: 47.915152 | M32: 0 | N32: 83 | O32: Strength/Gym (105 min) | P32: 1 | Q32: 105.43333 | R32: 531 | S32: =IF(COUNT(T32:V32)=3,T32+U32+V32,"") -> 354 | T32: 92 | U32: 204 | V32: 58 | W32: 4 | X32: 46184.122 | Y32: 46184.371 | Z32: 0 | AA32: 2385.1052
A33: 46185 | B33: P1 | C33: =A33-WEEKDAY(A33,3) -> 46181 | D33: 9563 | E33: 6.649 | F33: 5.322 | G33: 704 | H33: 153 | I33: 44 | J33: 66.240371 | K33: 137 | L33: 49.169903 | M33: 0 | N33: 83 | O33: Indoor workout (73 min) | P33: 1 | Q33: 73.183333 | R33: 436 | S33: =IF(COUNT(T33:V33)=3,T33+U33+V33,"") -> 212 | T33: 52 | U33: 113 | V33: 47 | W33: 13 | X33: 46185.228 | Y33: 46185.384 | Z33: 7 | AA33: 2444.1804
A34: 46186 | B34: P1 | C34: =A34-WEEKDAY(A34,3) -> 46181 | D34: 4859 | E34: 3.266 | F34: 2.647 | G34: 463 | H34: 115 | I34: 40 | J34: 66.30318 | K34: 123 | L34: 49.102222 | M34: 0 | N34: 83 | O34: Strength/Gym (65 min) | P34: 1 | Q34: 65.033333 | R34: 305 | S34: =IF(COUNT(T34:V34)=3,T34+U34+V34,"") -> 457 | T34: 91 | U34: 268 | V34: 98 | W34: 12 | X34: 46186.108 | Y34: 46186.434 | Z34: 0 | AA34: 2110.8569
A35: 46187 | B35: P1 | C35: =A35-WEEKDAY(A35,3) -> 46181 | D35: 17087 | E35: 12.685 | F35: 9.581 | G35: 1705 | H35: 233 | I35: 40 | J35: 71.147235 | K35: 176 | L35: 45.949886 | M35: 104 | N35: 83 | O35: Walk/Jog (38 min); Indoor cardio/HIIT (108 min) | P35: 2 | Q35: 145.93333 | R35: 1350.8743 | S35: =IF(COUNT(T35:V35)=3,T35+U35+V35,"") -> 489 | T35: 128 | U35: 254 | V35: 107 | W35: 9 | X35: 46187.067 | Y35: 46187.412 | Z35: 0 | AA35: 3545.8212
A36: 46188 | B36: P1 | C36: =A36-WEEKDAY(A36,3) -> 46188 | D36: 5810 | E36: 3.971 | F36: 3.259 | G36: 497 | H36: 73 | I36: 45 | J36: 70.65625 | K36: 139 | L36: 50.838798 | M36: 0 | N36: 83 | O36: Strength/Gym (44 min) | P36: 1 | Q36: 44.033333 | R36: 301 | S36: =IF(COUNT(T36:V36)=3,T36+U36+V36,"") -> 360 | T36: 59 | U36: 212 | V36: 89 | W36: 5 | X36: 46188.14 | Y36: 46188.394 | Z36: 5 | AA36: 2146.7926
A37: 46189 | B37: P1 | C37: =A37-WEEKDAY(A37,3) -> 46188 | D37: 5062 | E37: 3.466 | F37: 2.749 | G37: 179 | H37: 107 | I37: 50 | J37: 69.020833 | K37: 117 | L37: 58.545205 | M37: 0 | N37: 83 | P37: 0 | Q37: 0 | R37: 0 | S37: =IF(COUNT(T37:V37)=3,T37+U37+V37,"") -> 392 | T37: 40 | U37: 279 | V37: 73 | W37: 49 | X37: 46189.088 | Y37: 46189.394 | Z37: 1 | AA37: 1804.7261
A38: 46190 | B38: P1 | C38: =A38-WEEKDAY(A38,3) -> 46188 | D38: 16400 | E38: 13.365 | F38: 9.993 | G38: 924 | H38: 181 | I38: 42 | J38: 74.505965 | K38: 180 | L38: 50.316456 | M38: 50 | N38: 83 | O38: Running (51 min) | P38: 1 | Q38: 50.75 | R38: 642.25586 | S38: =IF(COUNT(T38:V38)=3,T38+U38+V38,"") -> 229 | T38: 28 | U38: 144 | V38: 57 | W38: 7 | X38: 46190.033 | Y38: 46190.197 | Z38: 7 | AA38: 2618.6225
A39: 46191 | B39: P1 | C39: =A39-WEEKDAY(A39,3) -> 46188 | D39: 9327 | E39: 6.198 | F39: 5.106 | G39: 1046 | H39: 275 | I39: 42 | J39: 65.088194 | K39: 123 | M39: 0 | N39: 83 | O39: Indoor workout (271 min) | P39: 1 | Q39: 270.9 | R39: 864 | S39: =IF(COUNT(T39:V39)=3,T39+U39+V39,"") -> 375 | T39: 57 | U39: 218 | V39: 100 | W39: 6 | X39: 46191.191 | Y39: 46191.456 | Z39: 0 | AA39: 2875.8257
A40: 46192 | B40: P1 | C40: =A40-WEEKDAY(A40,3) -> 46188 | D40: 9497 | E40: 6.747 | F40: 5.297 | G40: 493 | H40: 163 | I40: 40 | J40: 62.445483 | K40: 133 | L40: 46.311538 | M40: 0 | N40: 83 | O40: Strength/Gym (60 min) | P40: 1 | Q40: 60.05 | R40: 195 | S40: =IF(COUNT(T40:V40)=3,T40+U40+V40,"") -> 338 | T40: 66 | U40: 191 | V40: 81 | W40: 11 | X40: 46192.13 | Y40: 46192.372 | Z40: 0 | AA40: 2192.7492
...

Sheet Workout Sessions
A1: Date (IST) | B1: Period | C1: Type Code | D1: Inferred Activity | E1: Start (IST) | F1: Duration (min) | G1: Distance (m) | H1: Avg Pace raw (s/m) | I1: Pace (min/km) | J1: Calories (kcal) | K1: kcal / min | L1: Avg HR (bpm) | M1: Max HR (bpm)
A2: 46155 | B2: P1 | C2: 52 | D2: Strength/Gym | E2: 46155.654 | F2: 27.7 | I2: =IF(AND(G2>=500,H2>0),H2*1000/60,"") | J2: 122 | K2: =IF(F2>0,J2/F2,"") -> 4.4043321 | L2: 96.9 | M2: 121
A3: 46155 | B3: P1 | C3: 49 | D3: Indoor cardio/HIIT | E3: 46155.72 | F3: 93.7 | I3: =IF(AND(G3>=500,H3>0),H3*1000/60,"") | J3: 1139 | K3: =IF(F3>0,J3/F3,"") -> 12.155816 | L3: 159.8 | M3: 178
A4: 46156 | B4: P1 | C4: 52 | D4: Strength/Gym | E4: 46156.784 | F4: 55.4 | I4: =IF(AND(G4>=500,H4>0),H4*1000/60,"") | J4: 257 | K4: =IF(F4>0,J4/F4,"") -> 4.6389892 | L4: 98.6 | M4: 125
A5: 46157 | B5: P1 | C5: 52 | D5: Strength/Gym | E5: 46157.854 | F5: 51.6 | I5: =IF(AND(G5>=500,H5>0),H5*1000/60,"") | J5: 114 | K5: =IF(F5>0,J5/F5,"") -> 2.2093023 | L5: 78.3 | M5: 109
A6: 46160 | B6: P1 | C6: 52 | D6: Strength/Gym | E6: 46160.642 | F6: 44.8 | I6: =IF(AND(G6>=500,H6>0),H6*1000/60,"") | J6: 208 | K6: =IF(F6>0,J6/F6,"") -> 4.6428571 | L6: 98.7 | M6: 120
A7: 46160 | B7: P1 | C7: 1 | D7: Running | E7: 46160.841 | F7: 31.3 | G7: 5321 | H7: 0.35218944 | I7: =IF(AND(G7>=500,H7>0),H7*1000/60,"") -> 5.869824 | J7: 425.26315 | K7: =IF(F7>0,J7/F7,"") -> 13.586682 | L7: 174.2 | M7: 189
A8: 46161 | B8: P1 | C8: 6 | D8: Walk/Jog | E8: 46161.783 | F8: 43.6 | G8: 3076 | H8: 0.84980494 | I8: =IF(AND(G8>=500,H8>0),H8*1000/60,"") -> 14.163416 | J8: 140.92671 | K8: =IF(F8>0,J8/F8,"") -> 3.232264 | L8: 87.4 | M8: 98
A9: 46161 | B9: P1 | C9: 52 | D9: Strength/Gym | E9: 46161.825 | F9: 59.9 | I9: =IF(AND(G9>=500,H9>0),H9*1000/60,"") | J9: 213 | K9: =IF(F9>0,J9/F9,"") -> 3.5559265 | L9: 89.8 | M9: 109
A10: 46162 | B10: P1 | C10: 10 | D10: Indoor workout | E10: 46162.719 | F10: 50.9 | I10: =IF(AND(G10>=500,H10>0),H10*1000/60,"") | J10: 348 | K10: =IF(F10>0,J10/F10,"") -> 6.8369352 | L10: 117.3 | M10: 132
A11: 46163 | B11: P1 | C11: 52 | D11: Strength/Gym | E11: 46163.564 | F11: 50.8 | I11: =IF(AND(G11>=500,H11>0),H11*1000/60,"") | J11: 273 | K11: =IF(F11>0,J11/F11,"") -> 5.3740157 | L11: 104.8 | M11: 132
A12: 46163 | B12: P1 | C12: 1 | D12: Running | E12: 46163.876 | F12: 28.3 | G12: 5079 | H12: 0.333924 | I12: =IF(AND(G12>=500,H12>0),H12*1000/60,"") -> 5.5654 | J12: 368.56531 | K12: =IF(F12>0,J12/F12,"") -> 13.023509 | L12: 169.9 | M12: 187
A13: 46164 | B13: P1 | C13: 52 | D13: Strength/Gym | E13: 46164.854 | F13: 44.3 | I13: =IF(AND(G13>=500,H13>0),H13*1000/60,"") | J13: 174 | K13: =IF(F13>0,J13/F13,"") -> 3.9277652 | L13: 92.9 | M13: 122
A14: 46165 | B14: P1 | C14: 85 | D14: High-intensity indoor (85) | E14: 46165.706 | F14: 71.5 | I14: =IF(AND(G14>=500,H14>0),H14*1000/60,"") | J14: 850 | K14: =IF(F14>0,J14/F14,"") -> 11.888112 | L14: 158.7 | M14: 179
A15: 46166 | B15: P1 | C15: 1 | D15: Running | E15: 46166.311 | F15: 40 | G15: 6078 | H15: 0.39420862 | I15: =IF(AND(G15>=500,H15>0),H15*1000/60,"") -> 6.5701437 | J15: 531.37769 | K15: =IF(F15>0,J15/F15,"") -> 13.284442 | L15: 170.5 | M15: 179
A16: 46166 | B16: P1 | C16: 1 | D16: Running | E16: 46166.393 | F16: 18.8 | G16: 3178 | H16: 0.35431089 | I16: =IF(AND(G16>=500,H16>0),H16*1000/60,"") -> 5.9051815 | J16: 246.15851 | K16: =IF(F16>0,J16/F16,"") -> 13.093538 | L16: 169.6 | M16: 180
A17: 46166 | B17: P1 | C17: 49 | D17: Indoor cardio/HIIT | E17: 46166.747 | F17: 65.7 | I17: =IF(AND(G17>=500,H17>0),H17*1000/60,"") | J17: 644 | K17: =IF(F17>0,J17/F17,"") -> 9.8021309 | L17: 141.1 | M17: 165
A18: 46167 | B18: P1 | C18: 52 | D18: Strength/Gym | E18: 46167.813 | F18: 36.7 | I18: =IF(AND(G18>=500,H18>0),H18*1000/60,"") | J18: 153 | K18: =IF(F18>0,J18/F18,"") -> 4.1689373 | L18: 94.6 | M18: 117
A19: 46168 | B19: P1 | C19: 85 | D19: High-intensity indoor (85) | E19: 46168.371 | F19: 64.8 | I19: =IF(AND(G19>=500,H19>0),H19*1000/60,"") | J19: 381 | K19: =IF(F19>0,J19/F19,"") -> 5.8796296 | L19: 108.8 | M19: 166
A20: 46169 | B20: P1 | C20: 10 | D20: Indoor workout | E20: 46169.718 | F20: 51.8 | I20: =IF(AND(G20>=500,H20>0),H20*1000/60,"") | J20: 400 | K20: =IF(F20>0,J20/F20,"") -> 7.7220077 | L20: 124.1 | M20: 138
A21: 46169 | B21: P1 | C21: 52 | D21: Strength/Gym | E21: 46169.846 | F21: 41.6 | I21: =IF(AND(G21>=500,H21>0),H21*1000/60,"") | J21: 157 | K21: =IF(F21>0,J21/F21,"") -> 3.7740385 | L21: 91.1 | M21: 126
A22: 46171 | B22: P1 | C22: 1 | D22: Running | E22: 46171.24 | F22: 66.1 | G22: 10352 | H22: 0.38292117 | I22: =IF(AND(G22>=500,H22>0),H22*1000/60,"") -> 6.3820196 | J22: 840.22235 | K22: =IF(F22>0,J22/F22,"") -> 12.711382 | L22: 166.3 | M22: 179
A23: 46171 | B23: P1 | C23: 6 | D23: Walk/Jog | E23: 46171.791 | F23: 28.4 | G23: 1723 | H23: 0.98781196 | I23: =IF(AND(G23>=500,H23>0),H23*1000/60,"") -> 16.463533 | J23: 67.262886 | K23: =IF(F23>0,J23/F23,"") -> 2.3684115 | L23: 71.2 | M23: 87
A24: 46171 | B24: P1 | C24: 227 | D24: Indoor workout | E24: 46171.957 | F24: 46.4 | I24: =IF(AND(G24>=500,H24>0),H24*1000/60,"") | J24: 305 | K24: =IF(F24>0,J24/F24,"") -> 6.5732759 | L24: 103 | M24: 128
A25: 46172 | B25: P1 | C25: 49 | D25: Indoor cardio/HIIT | E25: 46172.292 | F25: 89.6 | I25: =IF(AND(G25>=500,H25>0),H25*1000/60,"") | J25: 878 | K25: =IF(F25>0,J25/F25,"") -> 9.7991071 | L25: 142.9 | M25: 177
A26: 46173 | B26: P1 | C26: 1 | D26: Running | E26: 46173.351 | F26: 21.1 | G26: 3122 | H26: 0.40358744 | I26: =IF(AND(G26>=500,H26>0),H26*1000/60,"") -> 6.7264574 | J26: 251.07634 | K26: =IF(F26>0,J26/F26,"") -> 11.899353 | L26: 157.9 | M26: 180
A27: 46173 | B27: P1 | C27: 52 | D27: Strength/Gym | E27: 46173.655 | F27: 30.6 | I27: =IF(AND(G27>=500,H27>0),H27*1000/60,"") | J27: 326 | K27: =IF(F27>0,J27/F27,"") -> 10.653595 | L27: 89.6 | M27: 121
A28: 46173 | B28: P1 | C28: 49 | D28: Indoor cardio/HIIT | E28: 46173.718 | F28: 107.5 | I28: =IF(AND(G28>=500,H28>0),H28*1000/60,"") | J28: 1099 | K28: =IF(F28>0,J28/F28,"") -> 10.223256 | L28: 144.6 | M28: 175
A29: 46177 | B29: P1 | C29: 8 | D29: Walk/Jog | E29: 46177.745 | F29: 15.1 | G29: 1660 | H29: 0.54337349 | I29: =IF(AND(G29>=500,H29>0),H29*1000/60,"") -> 9.0562249 | J29: 200.8929 | K29: =IF(F29>0,J29/F29,"") -> 13.304165 | L29: 174.4 | M29: 184
A30: 46177 | B30: P1 | C30: 14 | D30: Indoor workout | E30: 46177.765 | F30: 70.9 | I30: =IF(AND(G30>=500,H30>0),H30*1000/60,"") | J30: 298 | K30: =IF(F30>0,J30/F30,"") -> 4.203103 | L30: 94.9 | M30: 117
A31: 46181 | B31: P1 | C31: 52 | D31: Strength/Gym | E31: 46181.867 | F31: 113.4 | I31: =IF(AND(G31>=500,H31>0),H31*1000/60,"") | J31: 449 | K31: =IF(F31>0,J31/F31,"") -> 3.9594356 | L31: 93.1 | M31: 128
A32: 46182 | B32: P1 | C32: 52 | D32: Strength/Gym | E32: 46182.87 | F32: 72.8 | I32: =IF(AND(G32>=500,H32>0),H32*1000/60,"") | J32: 359 | K32: =IF(F32>0,J32/F32,"") -> 4.9313187 | L32: 101.3 | M32: 131
A33: 46183 | B33: P1 | C33: 85 | D33: High-intensity indoor (85) | E33: 46183.794 | F33: 54.5 | I33: =IF(AND(G33>=500,H33>0),H33*1000/60,"") | J33: 602 | K33: =IF(F33>0,J33/F33,"") -> 11.045872 | L33: 149.7 | M33: 176
A34: 46184 | B34: P1 | C34: 52 | D34: Strength/Gym | E34: 46184.839 | F34: 105.4 | I34: =IF(AND(G34>=500,H34>0),H34*1000/60,"") | J34: 531 | K34: =IF(F34>0,J34/F34,"") -> 5.0379507 | L34: 101.8 | M34: 130
A35: 46185 | B35: P1 | C35: 227 | D35: Indoor workout | E35: 46185.825 | F35: 73.2 | I35: =IF(AND(G35>=500,H35>0),H35*1000/60,"") | J35: 436 | K35: =IF(F35>0,J35/F35,"") -> 5.9562842 | L35: 109.2 | M35: 137
A36: 46186 | B36: P1 | C36: 52 | D36: Strength/Gym | E36: 46186.565 | F36: 65 | I36: =IF(AND(G36>=500,H36>0),H36*1000/60,"") | J36: 305 | K36: =IF(F36>0,J36/F36,"") -> 4.6923077 | L36: 98.8 | M36: 123
A37: 46187 | B37: P1 | C37: 8 | D37: Walk/Jog | E37: 46187.54 | F37: 37.6 | G37: 2835 | H37: 0.79435626 | I37: =IF(AND(G37>=500,H37>0),H37*1000/60,"") -> 13.239271 | J37: 271.8743 | K37: =IF(F37>0,J37/F37,"") -> 7.2306994 | L37: 145.9 | M37: 176
A38: 46187 | B38: P1 | C38: 49 | D38: Indoor cardio/HIIT | E38: 46187.922 | F38: 108.4 | I38: =IF(AND(G38>=500,H38>0),H38*1000/60,"") | J38: 1079 | K38: =IF(F38>0,J38/F38,"") -> 9.9538745 | L38: 142.6 | M38: 174
A39: 46188 | B39: P1 | C39: 52 | D39: Strength/Gym | E39: 46188.876 | F39: 44 | I39: =IF(AND(G39>=500,H39>0),H39*1000/60,"") | J39: 301 | K39: =IF(F39>0,J39/F39,"") -> 6.8409091 | L39: 116.6 | M39: 139
A40: 46190 | B40: P1 | C40: 1 | D40: Running | E40: 46190.243 | F40: 50.8 | G40: 8135 | H40: 0.37393977 | I40: =IF(AND(G40>=500,H40>0),H40*1000/60,"") -> 6.2323294 | J40: 642.25586 | K40: =IF(F40>0,J40/F40,"") -> 12.642832 | L40: 165 | M40: 180
...

Sheet HRV (Monthly)
A1: Month | B1: Baseline (ms) | C1: Monthly Min (ms) | D1: Monthly Max (ms) | E1: Last Reading (ms) | F1: Last Reading Date | G1: Note
A2: 2026-05 | B2: 91 | C2: 52 | D2: 125 | E2: 82 | F2: 46173 | G2: Readings start around 14 May
A3: 2026-06 | B3: 83 | C3: 55 | D3: 122 | E3: 70 | F3: 46203 | G3: Gap of about 2 days around 25 Jun
A4: 2026-07 | B4: 80 | C4: 64 | D4: 94 | E4: 94 | F4: 46234
A5: 2026-08 | B5: 81 | C5: 58 | D5: 117 | E5: 95 | F5: 46265
A6: 2026-09 | B6: 83 | C6: 63 | D6: 108 | E6: 94 | F6: 46295
A7: 2026-10 | B7: 82 | C7: 55 | D7: 112 | E7: 82 | F7: 46311 | G7: Partial month (1-16 Oct)
A9: Source: Zepp app, Heart Rate Variability > Month view (overnight HRV). Entered by hand from screenshots; daily values aren't available in the export.

Sheet Period Comparison
A1: Metric | B1: P1: 12 May – 20 Jul 2026 | C1: P2: 21 Jul – 28 Sep 2026 | D1: Change (P1 → P2) | E1: % Change
A2: Days | B2: =COUNTIF('Daily Summary'!$B$2:$B$141,"P1") -> 70 | C2: =COUNTIF('Daily Summary'!$B$2:$B$141,"P2") -> 70 | D2: =C2-B2 -> 0 | E2: =IF(B2=0,"",(C2-B2)/B2) -> 0
A3: Avg steps / day | B3: =AVERAGEIFS('Daily Summary'!$D$2:$D$141,'Daily Summary'!$B$2:$B$141,"P1") -> 7893.2143 | C3: =AVERAGEIFS('Daily Summary'!$D$2:$D$141,'Daily Summary'!$B$2:$B$141,"P2") -> 7822.7714 | D3: =C3-B3 -> -70.442857 | E3: =IF(B3=0,"",(C3-B3)/B3) -> -0.0089244831
A4: Avg distance / day (km) | B4: =AVERAGEIFS('Daily Summary'!$E$2:$E$141,'Daily Summary'!$B$2:$B$141,"P1") -> 5.7730143 | C4: =AVERAGEIFS('Daily Summary'!$E$2:$E$141,'Daily Summary'!$B$2:$B$141,"P2") -> 5.6913714 | D4: =C4-B4 -> -0.081642857 | E4: =IF(B4=0,"",(C4-B4)/B4) -> -0.014142154
A5: Avg active minutes / day | B5: =AVERAGEIFS('Daily Summary'!$H$2:$H$141,'Daily Summary'!$B$2:$B$141,"P1") -> 148.87143 | C5: =AVERAGEIFS('Daily Summary'!$H$2:$H$141,'Daily Summary'!$B$2:$B$141,"P2") -> 157.74286 | D5: =C5-B5 -> 8.8714286 | E5: =IF(B5=0,"",(C5-B5)/B5) -> 0.05959121
A6: Avg activity calories / day | B6: =AVERAGEIFS('Daily Summary'!$G$2:$G$141,'Daily Summary'!$B$2:$B$141,"P1") -> 627.52857 | C6: =AVERAGEIFS('Daily Summary'!$G$2:$G$141,'Daily Summary'!$B$2:$B$141,"P2") -> 646.67143 | D6: =C6-B6 -> 19.142857 | E6: =IF(B6=0,"",(C6-B6)/B6) -> 0.030505156
A7: Avg resting HR (bpm) | B7: =AVERAGEIFS('Daily Summary'!$I$2:$I$141,'Daily Summary'!$B$2:$B$141,"P1") -> 42.214286 | C7: =AVERAGEIFS('Daily Summary'!$I$2:$I$141,'Daily Summary'!$B$2:$B$141,"P2") -> 41.4 | D7: =C7-B7 -> -0.81428571 | E7: =IF(B7=0,"",(C7-B7)/B7) -> -0.01928934
A8: Avg sleeping HR (bpm) | B8: =AVERAGEIFS('Daily Summary'!$L$2:$L$141,'Daily Summary'!$B$2:$B$141,"P1") -> 48.606606 | C8: =AVERAGEIFS('Daily Summary'!$L$2:$L$141,'Daily Summary'!$B$2:$B$141,"P2") -> 47.369828 | D8: =C8-B8 -> -1.2367778 | E8: =IF(B8=0,"",(C8-B8)/B8) -> -0.025444644
A9: Avg HRV baseline (ms) | B9: =AVERAGEIFS('Daily Summary'!$N$2:$N$141,'Daily Summary'!$B$2:$B$141,"P1") -> 84.428571 | C9: =AVERAGEIFS('Daily Summary'!$N$2:$N$141,'Daily Summary'!$B$2:$B$141,"P2") -> 81.642857 | D9: =C9-B9 -> -2.7857143 | E9: =IF(B9=0,"",(C9-B9)/B9) -> -0.032994924
A10: Avg daily HR (bpm) | B10: =AVERAGEIFS('Daily Summary'!$J$2:$J$141,'Daily Summary'!$B$2:$B$141,"P1") -> 65.040907 | C10: =AVERAGEIFS('Daily Summary'!$J$2:$J$141,'Daily Summary'!$B$2:$B$141,"P2") -> 62.101589 | D10: =C10-B10 -> -2.9393178 | E10: =IF(B10=0,"",(C10-B10)/B10) -> -0.045191833
A11: Avg vigorous minutes / day | B11: =AVERAGEIFS('Daily Summary'!$M$2:$M$141,'Daily Summary'!$B$2:$B$141,"P1") -> 19.171429 | C11: =AVERAGEIFS('Daily Summary'!$M$2:$M$141,'Daily Summary'!$B$2:$B$141,"P2") -> 23.957143 | D11: =C11-B11 -> 4.7857143 | E11: =IF(B11=0,"",(C11-B11)/B11) -> 0.24962742
A12: Workout days | B12: =COUNTIFS('Daily Summary'!$B$2:$B$141,"P1",'Daily Summary'!$P$2:$P$141,">0") -> 50 | C12: =COUNTIFS('Daily Summary'!$B$2:$B$141,"P2",'Daily Summary'!$P$2:$P$141,">0") -> 46 | D12: =C12-B12 -> -4 | E12: =IF(B12=0,"",(C12-B12)/B12) -> -0.08
A13: Workout sessions | B13: =SUMIFS('Daily Summary'!$P$2:$P$141,'Daily Summary'!$B$2:$B$141,"P1") -> 66 | C13: =SUMIFS('Daily Summary'!$P$2:$P$141,'Daily Summary'!$B$2:$B$141,"P2") -> 73 | D13: =C13-B13 -> 7 | E13: =IF(B13=0,"",(C13-B13)/B13) -> 0.10606061
A14: Avg workout minutes / day | B14: =AVERAGEIFS('Daily Summary'!$Q$2:$Q$141,'Daily Summary'!$B$2:$B$141,"P1") -> 57.081429 | C14: =AVERAGEIFS('Daily Summary'!$Q$2:$Q$141,'Daily Summary'!$B$2:$B$141,"P2") -> 56.529524 | D14: =C14-B14 -> -0.55190476 | E14: =IF(B14=0,"",(C14-B14)/B14) -> -0.0096687272
A15: Avg workout calories / day | B15: =AVERAGEIFS('Daily Summary'!$R$2:$R$141,'Daily Summary'!$B$2:$B$141,"P1") -> 396.30927 | C15: =AVERAGEIFS('Daily Summary'!$R$2:$R$141,'Daily Summary'!$B$2:$B$141,"P2") -> 430.39989 | D15: =C15-B15 -> 34.090625 | E15: =IF(B15=0,"",(C15-B15)/B15) -> 0.086020257
A16: Avg sleep (hours) | B16: =AVERAGEIFS('Daily Summary'!$S$2:$S$141,'Daily Summary'!$B$2:$B$141,"P1")/60 -> 6.5466667 | C16: =AVERAGEIFS('Daily Summary'!$S$2:$S$141,'Daily Summary'!$B$2:$B$141,"P2")/60 -> 6.042381 | D16: =C16-B16 -> -0.50428571 | E16: =IF(B16=0,"",(C16-B16)/B16) -> -0.077029386
A17: Nights under 6 h | B17: =COUNTIFS('Daily Summary'!$B$2:$B$141,"P1",'Daily Summary'!$S$2:$S$141,"<360") -> 23 | C17: =COUNTIFS('Daily Summary'!$B$2:$B$141,"P2",'Daily Summary'!$S$2:$S$141,"<360") -> 36 | D17: =C17-B17 -> 13 | E17: =IF(B17=0,"",(C17-B17)/B17) -> 0.56521739
A18: Avg deep sleep (min) | B18: =AVERAGEIFS('Daily Summary'!$T$2:$T$141,'Daily Summary'!$B$2:$B$141,"P1") -> 68.085714 | C18: =AVERAGEIFS('Daily Summary'!$T$2:$T$141,'Daily Summary'!$B$2:$B$141,"P2") -> 63.842857 | D18: =C18-B18 -> -4.2428571 | E18: =IF(B18=0,"",(C18-B18)/B18) -> -0.062316408
A19: Avg REM sleep (min) | B19: =AVERAGEIFS('Daily Summary'!$V$2:$V$141,'Daily Summary'!$B$2:$B$141,"P1") -> 93.428571 | C19: =AVERAGEIFS('Daily Summary'!$V$2:$V$141,'Daily Summary'!$B$2:$B$141,"P2") -> 81.414286 | D19: =C19-B19 -> -12.014286 | E19: =IF(B19=0,"",(C19-B19)/B19) -> -0.12859327
A20: Deep sleep % of total | B20: =SUMIFS('Daily Summary'!$T$2:$T$141,'Daily Summary'!$B$2:$B$141,"P1")/SUMIFS('Daily Summary'!$S$2:$S$141,'Daily Summary'!$B$2:$B$141,"P1") -> 0.1733343 | C20: =SUMIFS('Daily Summary'!$T$2:$T$141,'Daily Summary'!$B$2:$B$141,"P2")/SUMIFS('Daily Summary'!$S$2:$S$141,'Daily Summary'!$B$2:$B$141,"P2") -> 0.17609741 | D20: =C20-B20 -> 0.002763104 | E20: =IF(B20=0,"",(C20-B20)/B20) -> 0.015940896
A21: Runs logged | B21: =COUNTIFS('Workout Sessions'!$B$2:$B$140,"P1",'Workout Sessions'!$C$2:$C$140,1) -> 12 | C21: =COUNTIFS('Workout Sessions'!$B$2:$B$140,"P2",'Workout Sessions'!$C$2:$C$140,1) -> 10 | D21: =C21-B21 -> -2 | E21: =IF(B21=0,"",(C21-B21)/B21) -> -0.16666667
A22: Total run distance (km) | B22: =SUMIFS('Workout Sessions'!$G$2:$G$140,'Workout Sessions'!$B$2:$B$140,"P1",'Workout Sessions'!$C$2:$C$140,1)/1000 -> 84.699 | C22: =SUMIFS('Workout Sessions'!$G$2:$G$140,'Workout Sessions'!$B$2:$B$140,"P2",'Workout Sessions'!$C$2:$C$140,1)/1000 -> 63.644 | D22: =C22-B22 -> -21.055 | E22: =IF(B22=0,"",(C22-B22)/B22) -> -0.24858617
A23: Avg run pace (min/km) | B23: =AVERAGEIFS('Workout Sessions'!$I$2:$I$140,'Workout Sessions'!$B$2:$B$140,"P1",'Workout Sessions'!$C$2:$C$140,1) -> 6.4097828 | C23: =AVERAGEIFS('Workout Sessions'!$I$2:$I$140,'Workout Sessions'!$B$2:$B$140,"P2",'Workout Sessions'!$C$2:$C$140,1) -> 6.4307622 | D23: =C23-B23 -> 0.020979402 | E23: =IF(B23=0,"",(C23-B23)/B23) -> 0.0032730285
A24: Avg est. energy burned / day (kcal) | B24: =AVERAGEIFS('Daily Summary'!$AA$2:$AA$141,'Daily Summary'!$B$2:$B$141,"P1") -> 2276.7064 | C24: =AVERAGEIFS('Daily Summary'!$AA$2:$AA$141,'Daily Summary'!$B$2:$B$141,"P2") -> 2332.1783 | D24: =C24-B24 -> 55.471914 | E24: =IF(B24=0,"",(C24-B24)/B24) -> 0.024364984
A26: Lower is better for resting/sleeping HR and run pace (min/km). All values are formulas over the other tabs. See report/REPORT.md for significance tests.

Sheet Weekly Trends
A1: Week Start (Mon) | B1: Days | C1: Avg Steps | D1: Avg Resting HR | E1: Avg Sleeping HR | F1: Avg Sleep (h) | G1: Workout Sessions | H1: Avg Workout kcal / day | I1: Vigorous Minutes
A2: 46153 | B2: =COUNTIF('Daily Summary'!$C$2:$C$141,A2) -> 6 | C2: =AVERAGEIFS('Daily Summary'!$D$2:$D$141,'Daily Summary'!$C$2:$C$141,A2) -> 6153.8333 | D2: =AVERAGEIFS('Daily Summary'!$I$2:$I$141,'Daily Summary'!$C$2:$C$141,A2) -> 41.333333 | E2: =AVERAGEIFS('Daily Summary'!$L$2:$L$141,'Daily Summary'!$C$2:$C$141,A2) -> 47.55035 | F2: =AVERAGEIFS('Daily Summary'!$S$2:$S$141,'Daily Summary'!$C$2:$C$141,A2)/60 -> 7.8694444 | G2: =SUMIFS('Daily Summary'!$P$2:$P$141,'Daily Summary'!$C$2:$C$141,A2) -> 4 | H2: =AVERAGEIFS('Daily Summary'!$R$2:$R$141,'Daily Summary'!$C$2:$C$141,A2) -> 272 | I2: =SUMIFS('Daily Summary'!$M$2:$M$141,'Daily Summary'!$C$2:$C$141,A2) -> 124
A3: 46160 | B3: =COUNTIF('Daily Summary'!$C$2:$C$141,A3) -> 7 | C3: =AVERAGEIFS('Daily Summary'!$D$2:$D$141,'Daily Summary'!$C$2:$C$141,A3) -> 8889.1429 | D3: =AVERAGEIFS('Daily Summary'!$I$2:$I$141,'Daily Summary'!$C$2:$C$141,A3) -> 43.285714 | E3: =AVERAGEIFS('Daily Summary'!$L$2:$L$141,'Daily Summary'!$C$2:$C$141,A3) -> 49.061891 | F3: =AVERAGEIFS('Daily Summary'!$S$2:$S$141,'Daily Summary'!$C$2:$C$141,A3)/60 -> 7.297619 | G3: =SUMIFS('Daily Summary'!$P$2:$P$141,'Daily Summary'!$C$2:$C$141,A3) -> 12 | H3: =AVERAGEIFS('Daily Summary'!$R$2:$R$141,'Daily Summary'!$C$2:$C$141,A3) -> 631.75591 | I3: =SUMIFS('Daily Summary'!$M$2:$M$141,'Daily Summary'!$C$2:$C$141,A3) -> 229
A4: 46167 | B4: =COUNTIF('Daily Summary'!$C$2:$C$141,A4) -> 7 | C4: =AVERAGEIFS('Daily Summary'!$D$2:$D$141,'Daily Summary'!$C$2:$C$141,A4) -> 10005.143 | D4: =AVERAGEIFS('Daily Summary'!$I$2:$I$141,'Daily Summary'!$C$2:$C$141,A4) -> 42.285714 | E4: =AVERAGEIFS('Daily Summary'!$L$2:$L$141,'Daily Summary'!$C$2:$C$141,A4) -> 49.162499 | F4: =AVERAGEIFS('Daily Summary'!$S$2:$S$141,'Daily Summary'!$C$2:$C$141,A4)/60 -> 5.6642857 | G4: =SUMIFS('Daily Summary'!$P$2:$P$141,'Daily Summary'!$C$2:$C$141,A4) -> 11 | H4: =AVERAGEIFS('Daily Summary'!$R$2:$R$141,'Daily Summary'!$C$2:$C$141,A4) -> 693.93737 | I4: =SUMIFS('Daily Summary'!$M$2:$M$141,'Daily Summary'!$C$2:$C$141,A4) -> 228
A5: 46174 | B5: =COUNTIF('Daily Summary'!$C$2:$C$141,A5) -> 7 | C5: =AVERAGEIFS('Daily Summary'!$D$2:$D$141,'Daily Summary'!$C$2:$C$141,A5) -> 7222.7143 | D5: =AVERAGEIFS('Daily Summary'!$I$2:$I$141,'Daily Summary'!$C$2:$C$141,A5) -> 41.285714 | E5: =AVERAGEIFS('Daily Summary'!$L$2:$L$141,'Daily Summary'!$C$2:$C$141,A5) -> 47.830339 | F5: =AVERAGEIFS('Daily Summary'!$S$2:$S$141,'Daily Summary'!$C$2:$C$141,A5)/60 -> 6.9642857 | G5: =SUMIFS('Daily Summary'!$P$2:$P$141,'Daily Summary'!$C$2:$C$141,A5) -> 2 | H5: =AVERAGEIFS('Daily Summary'!$R$2:$R$141,'Daily Summary'!$C$2:$C$141,A5) -> 71.270414 | I5: =SUMIFS('Daily Summary'!$M$2:$M$141,'Daily Summary'!$C$2:$C$141,A5) -> 20
A6: 46181 | B6: =COUNTIF('Daily Summary'!$C$2:$C$141,A6) -> 7 | C6: =AVERAGEIFS('Daily Summary'!$D$2:$D$141,'Daily Summary'!$C$2:$C$141,A6) -> 8492.5714 | D6: =AVERAGEIFS('Daily Summary'!$I$2:$I$141,'Daily Summary'!$C$2:$C$141,A6) -> 41.428571 | E6: =AVERAGEIFS('Daily Summary'!$L$2:$L$141,'Daily Summary'!$C$2:$C$141,A6) -> 47.86812 | F6: =AVERAGEIFS('Daily Summary'!$S$2:$S$141,'Daily Summary'!$C$2:$C$141,A6)/60 -> 6.0738095 | G6: =SUMIFS('Daily Summary'!$P$2:$P$141,'Daily Summary'!$C$2:$C$141,A6) -> 8 | H6: =AVERAGEIFS('Daily Summary'!$R$2:$R$141,'Daily Summary'!$C$2:$C$141,A6) -> 576.1249 | I6: =SUMIFS('Daily Summary'!$M$2:$M$141,'Daily Summary'!$C$2:$C$141,A6) -> 149
A7: 46188 | B7: =COUNTIF('Daily Summary'!$C$2:$C$141,A7) -> 7 | C7: =AVERAGEIFS('Daily Summary'!$D$2:$D$141,'Daily Summary'!$C$2:$C$141,A7) -> 8768.7143 | D7: =AVERAGEIFS('Daily Summary'!$I$2:$I$141,'Daily Summary'!$C$2:$C$141,A7) -> 42.714286 | E7: =AVERAGEIFS('Daily Summary'!$L$2:$L$141,'Daily Summary'!$C$2:$C$141,A7) -> 49.186259 | F7: =AVERAGEIFS('Daily Summary'!$S$2:$S$141,'Daily Summary'!$C$2:$C$141,A7)/60 -> 5.7809524 | G7: =SUMIFS('Daily Summary'!$P$2:$P$141,'Daily Summary'!$C$2:$C$141,A7) -> 6 | H7: =AVERAGEIFS('Daily Summary'!$R$2:$R$141,'Daily Summary'!$C$2:$C$141,A7) -> 366.46512 | I7: =SUMIFS('Daily Summary'!$M$2:$M$141,'Daily Summary'!$C$2:$C$141,A7) -> 51
A8: 46195 | B8: =COUNTIF('Daily Summary'!$C$2:$C$141,A8) -> 7 | C8: =AVERAGEIFS('Daily Summary'!$D$2:$D$141,'Daily Summary'!$C$2:$C$141,A8) -> 8758 | D8: =AVERAGEIFS('Daily Summary'!$I$2:$I$141,'Daily Summary'!$C$2:$C$141,A8) -> 43.714286 | E8: =AVERAGEIFS('Daily Summary'!$L$2:$L$141,'Daily Summary'!$C$2:$C$141,A8) -> 50.655079 | F8: =AVERAGEIFS('Daily Summary'!$S$2:$S$141,'Daily Summary'!$C$2:$C$141,A8)/60 -> 5.797619 | G8: =SUMIFS('Daily Summary'!$P$2:$P$141,'Daily Summary'!$C$2:$C$141,A8) -> 8 | H8: =AVERAGEIFS('Daily Summary'!$R$2:$R$141,'Daily Summary'!$C$2:$C$141,A8) -> 373.63467 | I8: =SUMIFS('Daily Summary'!$M$2:$M$141,'Daily Summary'!$C$2:$C$141,A8) -> 159
A9: 46202 | B9: =COUNTIF('Daily Summary'!$C$2:$C$141,A9) -> 7 | C9: =AVERAGEIFS('Daily Summary'!$D$2:$D$141,'Daily Summary'!$C$2:$C$141,A9) -> 8959.7143 | D9: =AVERAGEIFS('Daily Summary'!$I$2:$I$141,'Daily Summary'!$C$2:$C$141,A9) -> 41.714286 | E9: =AVERAGEIFS('Daily Summary'!$L$2:$L$141,'Daily Summary'!$C$2:$C$141,A9) -> 49.368239 | F9: =AVERAGEIFS('Daily Summary'!$S$2:$S$141,'Daily Summary'!$C$2:$C$141,A9)/60 -> 5.9619048 | G9: =SUMIFS('Daily Summary'!$P$2:$P$141,'Daily Summary'!$C$2:$C$141,A9) -> 4 | H9: =AVERAGEIFS('Daily Summary'!$R$2:$R$141,'Daily Summary'!$C$2:$C$141,A9) -> 491.58151 | I9: =SUMIFS('Daily Summary'!$M$2:$M$141,'Daily Summary'!$C$2:$C$141,A9) -> 236
A10: 46209 | B10: =COUNTIF('Daily Summary'!$C$2:$C$141,A10) -> 7 | C10: =AVERAGEIFS('Daily Summary'!$D$2:$D$141,'Daily Summary'!$C$2:$C$141,A10) -> 5449 | D10: =AVERAGEIFS('Daily Summary'!$I$2:$I$141,'Daily Summary'!$C$2:$C$141,A10) -> 41.714286 | E10: =AVERAGEIFS('Daily Summary'!$L$2:$L$141,'Daily Summary'!$C$2:$C$141,A10) -> 47.577096 | F10: =AVERAGEIFS('Daily Summary'!$S$2:$S$141,'Daily Summary'!$C$2:$C$141,A10)/60 -> 7.4285714 | G10: =SUMIFS('Daily Summary'!$P$2:$P$141,'Daily Summary'!$C$2:$C$141,A10) -> 4 | H10: =AVERAGEIFS('Daily Summary'!$R$2:$R$141,'Daily Summary'!$C$2:$C$141,A10) -> 152.14286 | I10: =SUMIFS('Daily Summary'!$M$2:$M$141,'Daily Summary'!$C$2:$C$141,A10) -> 0
A11: 46216 | B11: =COUNTIF('Daily Summary'!$C$2:$C$141,A11) -> 7 | C11: =AVERAGEIFS('Daily Summary'!$D$2:$D$141,'Daily Summary'!$C$2:$C$141,A11) -> 6344.1429 | D11: =AVERAGEIFS('Daily Summary'!$I$2:$I$141,'Daily Summary'!$C$2:$C$141,A11) -> 42.142857 | E11: =AVERAGEIFS('Daily Summary'!$L$2:$L$141,'Daily Summary'!$C$2:$C$141,A11) -> 48.147474 | F11: =AVERAGEIFS('Daily Summary'!$S$2:$S$141,'Daily Summary'!$C$2:$C$141,A11)/60 -> 7.3428571 | G11: =SUMIFS('Daily Summary'!$P$2:$P$141,'Daily Summary'!$C$2:$C$141,A11) -> 6 | H11: =AVERAGEIFS('Daily Summary'!$R$2:$R$141,'Daily Summary'!$C$2:$C$141,A11) -> 348.60851 | I11: =SUMIFS('Daily Summary'!$M$2:$M$141,'Daily Summary'!$C$2:$C$141,A11) -> 146
A12: 46223 | B12: =COUNTIF('Daily Summary'!$C$2:$C$141,A12) -> 7 | C12: =AVERAGEIFS('Daily Summary'!$D$2:$D$141,'Daily Summary'!$C$2:$C$141,A12) -> 7482.5714 | D12: =AVERAGEIFS('Daily Summary'!$I$2:$I$141,'Daily Summary'!$C$2:$C$141,A12) -> 41.142857 | E12: =AVERAGEIFS('Daily Summary'!$L$2:$L$141,'Daily Summary'!$C$2:$C$141,A12) -> 45.548693 | F12: =AVERAGEIFS('Daily Summary'!$S$2:$S$141,'Daily Summary'!$C$2:$C$141,A12)/60 -> 6.2928571 | G12: =SUMIFS('Daily Summary'!$P$2:$P$141,'Daily Summary'!$C$2:$C$141,A12) -> 6 | H12: =AVERAGEIFS('Daily Summary'!$R$2:$R$141,'Daily Summary'!$C$2:$C$141,A12) -> 368 | I12: =SUMIFS('Daily Summary'!$M$2:$M$141,'Daily Summary'!$C$2:$C$141,A12) -> 143
A13: 46230 | B13: =COUNTIF('Daily Summary'!$C$2:$C$141,A13) -> 7 | C13: =AVERAGEIFS('Daily Summary'!$D$2:$D$141,'Daily Summary'!$C$2:$C$141,A13) -> 9118.5714 | D13: =AVERAGEIFS('Daily Summary'!$I$2:$I$141,'Daily Summary'!$C$2:$C$141,A13) -> 41.714286 | E13: =AVERAGEIFS('Daily Summary'!$L$2:$L$141,'Daily Summary'!$C$2:$C$141,A13) -> 47.508154 | F13: =AVERAGEIFS('Daily Summary'!$S$2:$S$141,'Daily Summary'!$C$2:$C$141,A13)/60 -> 4.8714286 | G13: =SUMIFS('Daily Summary'!$P$2:$P$141,'Daily Summary'!$C$2:$C$141,A13) -> 8 | H13: =AVERAGEIFS('Daily Summary'!$R$2:$R$141,'Daily Summary'!$C$2:$C$141,A13) -> 459.13834 | I13: =SUMIFS('Daily Summary'!$M$2:$M$141,'Daily Summary'!$C$2:$C$141,A13) -> 187
... A21: 46286 | B21: =COUNTIF('Daily Summary'!$C$2:$C$141,A21) -> 7 | C21: =AVERAGEIFS('Daily Summary'!$D$2:$D$141,'Daily Summary'!$C$2:$C$141,A21) -> 9579.8571 | D21: =AVERAGEIFS('Daily Summary'!$I$2:$I$141,'Daily Summary'!$C$2:$C$141,A21) -> 40.857143 | E21: =AVERAGEIFS('Daily Summary'!$L$2:$L$141,'Daily Summary'!$C$2:$C$141,A21) -> 46.370413 | F21: =AVERAGEIFS('Daily Summary'!$S$2:$S$141,'Daily Summary'!$C$2:$C$141,A21)/60 -> 5.752381 | G21: =SUMIFS('Daily Summary'!$P$2:$P$141,'Daily Summary'!$C$2:$C$141,A21) -> 7 | H21: =AVERAGEIFS('Daily Summary'!$R$2:$R$141,'Daily Summary'!$C$2:$C$141,A21) -> 421.18175 | I21: =SUMIFS('Daily Summary'!$M$2:$M$141,'Daily Summary'!$C$2:$C$141,A21) -> 193
A23: Weeks with fewer than 4 days of data are left out so partial weeks don't distort the trend.

Sheet Notes
A1: Data sources & assumptions
A2: Covers 2026-05-12 to 2026-09-28 (140 days), merged from every 'Health Data*' export folder. Periods: P1: 12 May – 20 Jul 2026; P2: 21 Jul – 28 Sep 2026. A date that appears in two exports belongs to the earlier one; duplicate rows are de-duplicated with the newer export winning.
A3: Timezone: all times are IST (UTC+5:30). HEARTRATE_AUTO, ACTIVITY_MINUTE, ACTIVITY_STAGE and SLEEP_MINUTE are already local; SPORT start times and SLEEP start/stop are UTC in the export and are converted. The offset was confirmed by aligning workouts with heart-rate spikes (79 of 129 sessions of 20+ minutes peak at exactly +5:30).
A4: Workouts are assigned to their IST calendar date.
A5: Resting HR = lowest HEARTRATE_AUTO reading of the day. Sleeping HR = average HR across that night's sleep from SLEEP_MINUTE. There is no dedicated resting-HR field.
A6: Vigorous minutes = minutes with HR ≥ 140 bpm (70% of an age-predicted max of 200 for age 20).
A7: HRV is not in the export. The HRV tab and the Daily Summary's HRV column use monthly figures read off the Zepp app (manual_data/hrv_monthly.csv); add a row there each month to keep it current. Respiratory rate is not recorded (the column is empty in every export).
A8: Active Minutes = total duration of ACTIVITY_STAGE movement segments for that date.
A9: Activity Calories (device daily figure) already includes workout movement, so it overlaps Workout Calories; don't add them together.
A10: Workout names are inferred from Zepp's numeric type codes by distance, pace and intensity; the export has no names.
A11: Run pace (min/km) = SPORT avgPace (seconds per metre) × 1000 / 60, blank for sessions under 500 m (GPS dropouts, e.g. 2026-06-25 run: 59 min for 58 m).
A12: Sleep fields come from SLEEP; Total Sleep = Deep + Light + REM. The sleep row's date is the wake-up date.
... A16: Rebuild: python3 scripts/build_summary.py, then open the file in Excel once so formulas get calculated values.
